<?xml version="1.0"?>
<robot name="my_bot" xmlns:xacro="http://www.ros.org/wiki/xacro">

    <xacro:include filename="inertial_macros.xacro" />

    <material name="white">
        <color rgba="1 1 1 1"/>
    </material>
    <material name="orange">
        <color rgba="1 0.3 0.1 1"/>
    </material>
    <material name="blue">
        <color rgba="0.2 0.2 1 1"/>
    </material>
    <material name="black">
        <color rgba="0 0 0 1"/>
    </material>
    <material name="grey">
        <color rgba="0.5 0.5 0.5 1"/>
    </material>

    <link name="base_link"/>

    <!-- CHASSIS -->
    <joint name="chassis_joint" type="fixed">
        <parent link="base_link"/>
        <child link="chassis"/>
        <origin xyz="0 0 0"/>
    </joint>
    <link name="chassis">
        <visual>
            <origin xyz="0 0 0" rpy="0 0 0"/>
            <geometry>
                <mesh filename="package://my_bot/description/meshes/ROS2-Chasis.stl"
                      scale="0.001 0.001 0.001"/>
            </geometry>
            <material name="blue"/>
        </visual>
        <collision>
            <origin xyz="0 0 0" rpy="0 0 0"/>
            <geometry>
                <box size="0.3 0.3 0.15"/>
            </geometry>
        </collision>
        <xacro:inertial_box mass="0.5" x="0.3" y="0.3" z="0.15">
            <origin xyz="0 0 0" rpy="0 0 0"/>
        </xacro:inertial_box>
    </link>
    
<!-- FRONT LEFT WHEEL -->
<joint name="front_left_wheel_joint" type="continuous">
        <parent link="base_link"/>
        <child link="front_left_wheel"/>
        <origin xyz="0.16 0 0" rpy="1.570795 0 0"/> 
        <axis xyz="1 0 0"/> 
    </joint>

    <link name="front_left_wheel">
        <visual>
            <origin xyz="0 0 0" rpy="1.570795 0 0"/> 
            <geometry>
                <mesh filename="package://my_bot/description/meshes/ROS2-wheel_FL.stl"
                      scale="0.001 0.001 0.001"/>
            </geometry>
            <material name="black"/>
        </visual>
        
        <collision>
            <origin xyz="0 0 0" rpy="1.570795 0 0"/>
            <geometry>
                <cylinder length="0.04" radius="0.05"/>
            </geometry>
        </collision>
    </link>


</robot>
